<?xml version="1.0"?>
<robot xmlns:xacro="http://ros.org/wiki/xacro">

  <xacro:include filename="$(find cats)/urdf/common.xacro"/>

  <xacro:property name="wheel_radius" value="0.1245"/>
  <xacro:property name="wheel_width" value="0.073"/>
  <xacro:property name="wheel_mass" value="4.0"/>

  <xacro:macro name="wheel" params="prefix parent *joint_origin *joint_axis">
    <joint name="${prefix}_wheel_joint" type="continuous">
      <xacro:insert_block name="joint_origin"/>
      <parent link="${parent}"/>
      <child link="${prefix}_wheel_link"/>
      <xacro:insert_block name="joint_axis"/>
      <limit velocity="11.64" effort="11.25"/>
    </joint>

    <link name="${prefix}_wheel_link">
      <visual>
        <origin xyz="0 0 0" rpy="0 0 0"/>
        <geometry>
          <mesh filename="package://cats/meshes/STL/wheel.stl" scale="0.001 0.001 0.001"/>
        </geometry>
      </visual>
      <collision>
          <origin xyz="0 0 0" rpy="0 ${M_PI/2} 0"/>
        <geometry>
          <!-- <mesh filename="package://cats/meshes/STL/wheel.stl" scale="0.001 0.001 0.001"/> -->
          <cylinder radius="${wheel_radius}" length="${wheel_width}"/>
        </geometry>
      </collision>
      <inertial>
        <origin xyz="0 0 0" rpy="0 0 0"/>
        <cylinder_inertial mass="${wheel_mass}"
          radius="${wheel_radius}" length="${wheel_width}"/>
      </inertial>
    </link>
  </xacro:macro>

  <xacro:macro name="wheel_gazebo" params="prefix">
    <gazebo reference="${prefix}_wheel_link">
      <selfCollide>false</selfCollide>
      <mu1 value="0.8"/>
      <mu2 value="0.8"/>
    </gazebo>
  </xacro:macro>

  <xacro:macro name="wheel_trans" params="prefix">
    <transmission name="${prefix}_wheel_trans">
      <type>transmission_interface/SimpleTransmission</type>
      <joint name="${prefix}_wheel_joint">
        <hardwareInterface>hardware_interface/VelocityJointInterface</hardwareInterface>
      </joint>
      <actuator name="${prefix}_wheel_motor">
        <hardwareInterface>hardware_interface/VelocityJointInterface</hardwareInterface>
        <mechanicalReduction>30</mechanicalReduction>
      </actuator>
    </transmission>
  </xacro:macro>

</robot>
