<?xml version="1.0"?>
<robot xmlns:xacro="http://ros.org/wiki/xacro">

  <xacro:include filename="$(find cats)/urdf/common.xacro"/>

  <xacro:macro name="caster" params="prefix parent *joint_origin">
    <joint name="${prefix}_caster_joint" type="fixed">
      <insert_block name="joint_origin"/>
      <parent link="${parent}"/>
      <child link="${prefix}_caster_base_link"/>
    </joint>

    <link name="${prefix}_caster_base_link">
      <visual>
        <origin xyz="0 0.144608 -0.214894" rpy="${M_PI/2} 0 ${-M_PI/2}"/>
        <geometry>
          <mesh filename="package://cats/meshes/STL/caster/caster_base.stl" scale="0.001 0.001 0.001"/>
        </geometry>
      </visual>
      <collision>
        <origin xyz="0 0 0" rpy="0 0 0"/>
        <geometry>
          <cylinder radius="0.0365" length="0.023"/>
        </geometry>
      </collision>
      <inertial>
        <origin xyz="0 0 0" rpy="0 0 0"/>
        <cylinder_inertial mass="0.500" radius="0.0365" length="0.023"/>
      </inertial>
    </link>

    <joint name="${prefix}_caster_arm_joint" type="continuous">
      <origin xyz="0 0 -0.009" rpy="0 0 0"/>
      <parent link="${prefix}_caster_base_link"/>
      <child link="${prefix}_caster_arm_link"/>
      <axis xyz="0 0 1"/>
      <limit velocity="17.45" effort="7.5"/>
    </joint>

    <link name="${prefix}_caster_arm_link">
      <visual>
        <origin xyz="-0.144608 0 -0.205602" rpy="${M_PI/2} 0 0"/>
        <geometry>
          <mesh filename="package://cats/meshes/STL/caster/caster_arm.stl" scale="0.001 0.001 0.001"/>
        </geometry>
      </visual>
      <collision>
        <origin xyz="0 0 0" rpy="0 0 0"/>
        <geometry>
          <cylinder radius="0.0365" length="0.023"/>
        </geometry>
      </collision>
      <inertial>
        <origin xyz="0 0 0" rpy="0 0 0"/>
        <cylinder_inertial mass="0.500" radius="0.0365" length="0.023"/>
      </inertial>
    </link>

    <joint name="${prefix}_caster_wheel_joint" type="continuous">
      <origin xyz="-0.044987 0 -0.101525" rpy="0 0 0"/>
      <parent link="${prefix}_caster_arm_link"/>
      <child link="${prefix}_caster_wheel_link"/>
      <axis xyz="0 1 0"/>
      <limit velocity="17.45" effort="7.5"/>
    </joint>

    <link name="${prefix}_caster_wheel_link">
      <visual>
        <origin xyz="-0.099621 0 -0.104369" rpy="${M_PI/2} 0 0"/>
        <geometry>
          <mesh filename="package://cats/meshes/STL/caster/caster_wheel.stl" scale="0.001 0.001 0.001"/>
        </geometry>
      </visual>
      <collision>
        <origin xyz="0 0 0" rpy="${M_PI/2} 0 0"/>
        <geometry>
          <cylinder radius="0.050" length="0.030"/>
        </geometry>
      </collision>
      <inertial>
        <origin xyz="0 0 0" rpy="${M_PI/2} 0 0"/>
        <cylinder_inertial mass="0.500" radius="0.050" length="0.030"/>
      </inertial>
    </link>
  </xacro:macro>

  <xacro:macro name="caster_gazebo" params="prefix">
    <gazebo reference="${prefix}_caster_base_link">
      <selfCollide>false</selfCollide>
      <mu1 value="0"/>
      <mu2 value="0"/>
    </gazebo>
    <gazebo reference="${prefix}_caster_arm_link">
      <selfCollide>false</selfCollide>
      <mu1 value="0.05"/>
      <mu2 value="0.05"/>
    </gazebo>
    <gazebo reference="${prefix}_caster_wheel_link">
      <selfCollide>false</selfCollide>
      <mu1 value="0.8"/>
      <mu2 value="0.8"/>
    </gazebo>
  </xacro:macro>

  </robot>
